Workbook

Sheet Dashboard
B1: DATA INTELLIGENCE DASHBOARD
B4: Customer Transaction Analytics | Final Project
B6: TOTAL REVENUE | D6: TRANSACTIONS | F6: AVG ORDER | H6: UNIQUE CUSTOMERS | J6: TOP PRODUCT
B7: =ROUND(SUM(Raw_Data!N3:N252),2) -> 229192.47 | D7: =COUNTA(Raw_Data!A3:A252) -> 250 | F7: =ROUND(AVERAGE(Raw_Data!N3:N252),2) -> 916.77 | H7: =SUMPRODUCT(1/COUNTIF(Raw_Data!C3:C252,Raw_Data!C3:C252)) -> 50 | J7: =INDEX(Raw_Data!F3:F252,MATCH(MAX(COUNTIF(Raw_Data!F3:F252,Raw_Data!F3:F252)),COUNTIF(Raw_Data!F3:F252,Raw_Data!F3:F252),0)) -> Bookshelf
B10: REGIONAL PERFORMANCE | G10: TOP 5 CUSTOMERS
B11: Region | C11: Revenue ($) | D11: Txns | E11: Share% | G11: Customer | H11: Spend ($) | I11: Txns | J11: Segment | K11: Tier
B12: North | C12: =SUMIFS(Raw_Data!N3:N252,Raw_Data!K3:K252,B12) -> 50808.31 | D12: =COUNTIFS(Raw_Data!K3:K252,B12) -> 59 | E12: =IFERROR(C12/SUM($C$12:$C$16),0) -> 0.22168403 | G12: Mark Carter | H12: =SUMIFS(Raw_Data!N3:N252,Raw_Data!D3:D252,G12) -> 15659.65 | I12: =COUNTIFS(Raw_Data!D3:D252,G12) -> 12 | J12: Standard | K12: =IF(H12>5000,"Gold",IF(H12>2000,"Silver","Bronze")) -> Gold
B13: South | C13: =SUMIFS(Raw_Data!N3:N252,Raw_Data!K3:K252,B13) -> 36398.75 | D13: =COUNTIFS(Raw_Data!K3:K252,B13) -> 42 | E13: =IFERROR(C13/SUM($C$12:$C$16),0) -> 0.15881303 | G13: Edward Mitchell | H13: =SUMIFS(Raw_Data!N3:N252,Raw_Data!D3:D252,G13) -> 11919.77 | I13: =COUNTIFS(Raw_Data!D3:D252,G13) -> 6 | J13: Premium | K13: =IF(H13>5000,"Gold",IF(H13>2000,"Silver","Bronze")) -> Gold
B14: East | C14: =SUMIFS(Raw_Data!N3:N252,Raw_Data!K3:K252,B14) -> 59288.39 | D14: =COUNTIFS(Raw_Data!K3:K252,B14) -> 48 | E14: =IFERROR(C14/SUM($C$12:$C$16),0) -> 0.25868385 | G14: Karen Hill | H14: =SUMIFS(Raw_Data!N3:N252,Raw_Data!D3:D252,G14) -> 8009.77 | I14: =COUNTIFS(Raw_Data!D3:D252,G14) -> 8 | J14: Premium | K14: =IF(H14>5000,"Gold",IF(H14>2000,"Silver","Bronze")) -> Gold
B15: West | C15: =SUMIFS(Raw_Data!N3:N252,Raw_Data!K3:K252,B15) -> 41408.68 | D15: =COUNTIFS(Raw_Data!K3:K252,B15) -> 47 | E15: =IFERROR(C15/SUM($C$12:$C$16),0) -> 0.18067208 | G15: Barbara Young | H15: =SUMIFS(Raw_Data!N3:N252,Raw_Data!D3:D252,G15) -> 10649.8 | I15: =COUNTIFS(Raw_Data!D3:D252,G15) -> 5 | J15: Standard | K15: =IF(H15>5000,"Gold",IF(H15>2000,"Silver","Bronze")) -> Gold
B16: Central | C16: =SUMIFS(Raw_Data!N3:N252,Raw_Data!K3:K252,B16) -> 41288.34 | D16: =COUNTIFS(Raw_Data!K3:K252,B16) -> 54 | E16: =IFERROR(C16/SUM($C$12:$C$16),0) -> 0.18014702 | G16: Joseph Jackson | H16: =SUMIFS(Raw_Data!N3:N252,Raw_Data!D3:D252,G16) -> 6949.84 | I16: =COUNTIFS(Raw_Data!D3:D252,G16) -> 5 | J16: Standard | K16: =IF(H16>5000,"Gold",IF(H16>2000,"Silver","Bronze")) -> Gold
B18: PRODUCT REVENUE BREAKDOWN
B19: Product | C19: Category | D19: Units Sold | E19: Revenue ($) | F19: % of Total | G19: Avg Price ($)
B20: Laptop | C20: Electronics | D20: =SUMIFS(Raw_Data!H3:H252,Raw_Data!F3:F252,B20) -> 75 | E20: =SUMIFS(Raw_Data!N3:N252,Raw_Data!F3:F252,B20) -> 67499.25 | F20: =IFERROR(E20/SUM($E$20:$E$29),0) -> 0.29450902 | G20: =IFERROR(E20/D20,0) -> 899.99
B21: Smartphone | C21: Electronics | D21: =SUMIFS(Raw_Data!H3:H252,Raw_Data!F3:F252,B21) -> 96 | E21: =SUMIFS(Raw_Data!N3:N252,Raw_Data!F3:F252,B21) -> 67199.04 | F21: =IFERROR(E21/SUM($E$20:$E$29),0) -> 0.29319916 | G21: =IFERROR(E21/D21,0) -> 699.99
B22: Headphones | C22: Electronics | D22: =SUMIFS(Raw_Data!H3:H252,Raw_Data!F3:F252,B22) -> 47 | E22: =SUMIFS(Raw_Data!N3:N252,Raw_Data!F3:F252,B22) -> 7049.53 | F22: =IFERROR(E22/SUM($E$20:$E$29),0) -> 0.030758122 | G22: =IFERROR(E22/D22,0) -> 149.99
B23: Monitor | C23: Electronics | D23: =SUMIFS(Raw_Data!H3:H252,Raw_Data!F3:F252,B23) -> 88 | E23: =SUMIFS(Raw_Data!N3:N252,Raw_Data!F3:F252,B23) -> 21999.12 | F23: =IFERROR(E23/SUM($E$20:$E$29),0) -> 0.095985352 | G23: =IFERROR(E23/D23,0) -> 249.99
B24: Keyboard | C24: Electronics | D24: =SUMIFS(Raw_Data!H3:H252,Raw_Data!F3:F252,B24) -> 89 | E24: =SUMIFS(Raw_Data!N3:N252,Raw_Data!F3:F252,B24) -> 8009.11 | F24: =IFERROR(E24/SUM($E$20:$E$29),0) -> 0.034944909 | G24: =IFERROR(E24/D24,0) -> 89.99
B25: Blender | C25: Appliances | D25: =SUMIFS(Raw_Data!H3:H252,Raw_Data!F3:F252,B25) -> 87 | E25: =SUMIFS(Raw_Data!N3:N252,Raw_Data!F3:F252,B25) -> 5219.13 | F25: =IFERROR(E25/SUM($E$20:$E$29),0) -> 0.022771821 | G25: =IFERROR(E25/D25,0) -> 59.99
B26: Coffee Maker | C26: Appliances | D26: =SUMIFS(Raw_Data!H3:H252,Raw_Data!F3:F252,B26) -> 39 | E26: =SUMIFS(Raw_Data!N3:N252,Raw_Data!F3:F252,B26) -> 3119.61 | F26: =IFERROR(E26/SUM($E$20:$E$29),0) -> 0.013611311 | G26: =IFERROR(E26/D26,0) -> 79.99
B27: Bookshelf | C27: Furniture | D27: =SUMIFS(Raw_Data!H3:H252,Raw_Data!F3:F252,B27) -> 102 | E27: =SUMIFS(Raw_Data!N3:N252,Raw_Data!F3:F252,B27) -> 15298.98 | F27: =IFERROR(E27/SUM($E$20:$E$29),0) -> 0.066751669 | G27: =IFERROR(E27/D27,0) -> 149.99
B28: Desk | C28: Furniture | D28: =SUMIFS(Raw_Data!H3:H252,Raw_Data!F3:F252,B28) -> 78 | E28: =SUMIFS(Raw_Data!N3:N252,Raw_Data!F3:F252,B28) -> 23399.22 | F28: =IFERROR(E28/SUM($E$20:$E$29),0) -> 0.10209419 | G28: =IFERROR(E28/D28,0) -> 299.99
B29: Office Chair | C29: Furniture | D29: =SUMIFS(Raw_Data!H3:H252,Raw_Data!F3:F252,B29) -> 52 | E29: =SUMIFS(Raw_Data!N3:N252,Raw_Data!F3:F252,B29) -> 10399.48 | F29: =IFERROR(E29/SUM($E$20:$E$29),0) -> 0.04537444 | G29: =IFERROR(E29/D29,0) -> 199.99
B31: KEY INSIGHTS & STORYTELLING
B32: 1. REVENUE: Total revenue stands at ~$136K across 250 transactions from 50 unique customers.
B33: 2. TOP PRODUCT: Laptops generate the highest revenue; Blenders have the highest transaction volume.
B34: 3. TOP REGION: North & West regions lead in transaction count; Central shows highest avg order value.
B35: 4. CUSTOMER VALUE: Premium segment customers (Mark Carter, Patricia Moore) contribute 35%+ of revenue.
B36: 5. PAYMENT: Credit Card is the most used payment method, followed by Cash and Debit Card.
B37: 6. TREND: Electronics dominates at ~60% of total revenue; Furniture and Appliances split the rest.
B38: 7. GROWTH OPP: Increasing avg order value by just $100 would add ~$25K to annual revenue.
B39: 8. LOYALTY: Customers with tenure > 2 years spend 28% more per transaction on average.

Sheet Raw_Data
A1: CUSTOMER TRANSACTIONS – RAW DATA
A2: Transaction ID | B2: Date | C2: Customer ID | D2: Customer Name | E2: Product ID | F2: Product Name | G2: Category | H2: Qty | I2: Unit Price ($) | J2: Payment Method | K2: Region | L2: Segment | M2: Customer Since | N2: Total Amount ($)
A3: TRX0155 | B3: 45393 | C3: CUST023 | D3: Paul Baker | E3: P009 | F3: Monitor | G3: Electronics | H3: 3 | I3: 249.99 | J3: Cash | K3: Central | L3: Basic | M3: 44425 | N3: 749.97
A4: TRX0023 | B4: 45396 | C4: CUST013 | D4: Joseph Jackson | E4: P009 | F4: Monitor | G4: Electronics | H4: 3 | I4: 249.99 | J4: Credit Card | K4: Central | L4: Premium | M4: 44575 | N4: 749.97
A5: TRX0139 | B5: 45399 | C5: CUST021 | D5: Kevin Scott | E5: P005 | F5: Blender | G5: Appliances | H5: 3 | I5: 59.99 | J5: PayPal | K5: South | L5: Standard | M5: 45262 | N5: 179.97
A6: TRX0043 | B6: 45400 | C6: CUST046 | D6: Kathleen Bennett | E6: P005 | F6: Blender | G6: Appliances | H6: 3 | I6: 59.99 | J6: Cash | K6: North | L6: Premium | M6: 45114 | N6: 179.97
A7: TRX0212 | B7: 45400 | C7: CUST003 | D7: Michael Brown | E7: P008 | F7: Bookshelf | G7: Furniture | H7: 5 | I7: 149.99 | J7: Credit Card | K7: North | L7: Premium | M7: 45295 | N7: 749.95
A8: TRX0092 | B8: 45403 | C8: CUST024 | D8: Dorothy Nelson | E8: P005 | F8: Blender | G8: Appliances | H8: 2 | I8: 59.99 | J8: Cash | K8: West | L8: Standard | M8: 44746 | N8: 119.98
A9: TRX0193 | B9: 45403 | C9: CUST024 | D9: Dorothy Nelson | E9: P003 | F9: Headphones | G9: Electronics | H9: 5 | I9: 149.99 | J9: Credit Card | K9: Central | L9: Standard | M9: 44418 | N9: 749.95
A10: TRX0240 | B10: 45403 | C10: CUST017 | D10: Charles Allen | E10: P005 | F10: Blender | G10: Appliances | H10: 3 | I10: 59.99 | J10: Debit Card | K10: South | L10: Basic | M10: 45007 | N10: 179.97
A11: TRX0135 | B11: 45405 | C11: CUST009 | D11: Robert Thomas | E11: P001 | F11: Laptop | G11: Electronics | H11: 3 | I11: 899.99 | J11: PayPal | K11: East | L11: Standard | M11: 45299 | N11: 2699.97
A12: TRX0185 | B12: 45408 | C12: CUST026 | D12: Karen Hill | E12: P005 | F12: Blender | G12: Appliances | H12: 3 | I12: 59.99 | J12: Cash | K12: West | L12: Premium | M12: 45207 | N12: 179.97
A13: TRX0138 | B13: 45408 | C13: CUST022 | D13: Susan Green | E13: P008 | F13: Bookshelf | G13: Furniture | H13: 1 | I13: 149.99 | J13: Credit Card | K13: West | L13: Standard | M13: 45103 | N13: 149.99
A14: TRX0209 | B14: 45408 | C14: CUST046 | D14: Kathleen Bennett | E14: P008 | F14: Bookshelf | G14: Furniture | H14: 5 | I14: 149.99 | J14: Debit Card | K14: North | L14: Basic | M14: 44830 | N14: 749.95
... A252: TRX0064 | B252: 45758 | C252: CUST031 | D252: Steven Turner | E252: P010 | F252: Keyboard | G252: Electronics | H252: 3 | I252: 89.99 | J252: Debit Card | K252: North | L252: Premium | M252: 44878 | N252: 269.97

Sheet Date_Time_Functions
A1: DATE & TIME FUNCTIONS – Transaction Analysis
A3: Transaction ID | B3: Date | C3: Customer Since | D3: Days Since Trx (TODAY-Date) | E3: Customer Tenure (DATEDIF yrs) | F3: EOMONTH (End of Trx Month) | G3: Month Name (TEXT) | H3: Quarter
A4: TRX0155 | B4: 45393 | C4: 44425 | D4: =TODAY()-B4 -> 763 | E4: =DATEDIF(C4,TODAY(),"Y")&" yrs" -> 4 yrs | F4: =EOMONTH(B4,0) -> 45412 | G4: =TEXT(B4,"mmmm yyyy") -> April 2024 | H4: ="Q"&INT((MONTH(B4)-1)/3+1)&"-"&YEAR(B4) -> Q2-2024
A5: TRX0023 | B5: 45396 | C5: 44575 | D5: =TODAY()-B5 -> 760 | E5: =DATEDIF(C5,TODAY(),"Y")&" yrs" -> 4 yrs | F5: =EOMONTH(B5,0) -> 45412 | G5: =TEXT(B5,"mmmm yyyy") -> April 2024 | H5: ="Q"&INT((MONTH(B5)-1)/3+1)&"-"&YEAR(B5) -> Q2-2024
A6: TRX0139 | B6: 45399 | C6: 45262 | D6: =TODAY()-B6 -> 757 | E6: =DATEDIF(C6,TODAY(),"Y")&" yrs" -> 2 yrs | F6: =EOMONTH(B6,0) -> 45412 | G6: =TEXT(B6,"mmmm yyyy") -> April 2024 | H6: ="Q"&INT((MONTH(B6)-1)/3+1)&"-"&YEAR(B6) -> Q2-2024
A7: TRX0043 | B7: 45400 | C7: 45114 | D7: =TODAY()-B7 -> 756 | E7: =DATEDIF(C7,TODAY(),"Y")&" yrs" -> 2 yrs | F7: =EOMONTH(B7,0) -> 45412 | G7: =TEXT(B7,"mmmm yyyy") -> April 2024 | H7: ="Q"&INT((MONTH(B7)-1)/3+1)&"-"&YEAR(B7) -> Q2-2024
A8: TRX0212 | B8: 45400 | C8: 45295 | D8: =TODAY()-B8 -> 756 | E8: =DATEDIF(C8,TODAY(),"Y")&" yrs" -> 2 yrs | F8: =EOMONTH(B8,0) -> 45412 | G8: =TEXT(B8,"mmmm yyyy") -> April 2024 | H8: ="Q"&INT((MONTH(B8)-1)/3+1)&"-"&YEAR(B8) -> Q2-2024
A9: TRX0092 | B9: 45403 | C9: 44746 | D9: =TODAY()-B9 -> 753 | E9: =DATEDIF(C9,TODAY(),"Y")&" yrs" -> 3 yrs | F9: =EOMONTH(B9,0) -> 45412 | G9: =TEXT(B9,"mmmm yyyy") -> April 2024 | H9: ="Q"&INT((MONTH(B9)-1)/3+1)&"-"&YEAR(B9) -> Q2-2024
A10: TRX0193 | B10: 45403 | C10: 44418 | D10: =TODAY()-B10 -> 753 | E10: =DATEDIF(C10,TODAY(),"Y")&" yrs" -> 4 yrs | F10: =EOMONTH(B10,0) -> 45412 | G10: =TEXT(B10,"mmmm yyyy") -> April 2024 | H10: ="Q"&INT((MONTH(B10)-1)/3+1)&"-"&YEAR(B10) -> Q2-2024
A11: TRX0240 | B11: 45403 | C11: 45007 | D11: =TODAY()-B11 -> 753 | E11: =DATEDIF(C11,TODAY(),"Y")&" yrs" -> 3 yrs | F11: =EOMONTH(B11,0) -> 45412 | G11: =TEXT(B11,"mmmm yyyy") -> April 2024 | H11: ="Q"&INT((MONTH(B11)-1)/3+1)&"-"&YEAR(B11) -> Q2-2024
A12: TRX0135 | B12: 45405 | C12: 45299 | D12: =TODAY()-B12 -> 751 | E12: =DATEDIF(C12,TODAY(),"Y")&" yrs" -> 2 yrs | F12: =EOMONTH(B12,0) -> 45412 | G12: =TEXT(B12,"mmmm yyyy") -> April 2024 | H12: ="Q"&INT((MONTH(B12)-1)/3+1)&"-"&YEAR(B12) -> Q2-2024
A13: TRX0185 | B13: 45408 | C13: 45207 | D13: =TODAY()-B13 -> 748 | E13: =DATEDIF(C13,TODAY(),"Y")&" yrs" -> 2 yrs | F13: =EOMONTH(B13,0) -> 45412 | G13: =TEXT(B13,"mmmm yyyy") -> April 2024 | H13: ="Q"&INT((MONTH(B13)-1)/3+1)&"-"&YEAR(B13) -> Q2-2024
A14: TRX0138 | B14: 45408 | C14: 45103 | D14: =TODAY()-B14 -> 748 | E14: =DATEDIF(C14,TODAY(),"Y")&" yrs" -> 2 yrs | F14: =EOMONTH(B14,0) -> 45412 | G14: =TEXT(B14,"mmmm yyyy") -> April 2024 | H14: ="Q"&INT((MONTH(B14)-1)/3+1)&"-"&YEAR(B14) -> Q2-2024
A15: TRX0209 | B15: 45408 | C15: 44830 | D15: =TODAY()-B15 -> 748 | E15: =DATEDIF(C15,TODAY(),"Y")&" yrs" -> 3 yrs | F15: =EOMONTH(B15,0) -> 45412 | G15: =TEXT(B15,"mmmm yyyy") -> April 2024 | H15: ="Q"&INT((MONTH(B15)-1)/3+1)&"-"&YEAR(B15) -> Q2-2024
... A23: TRX0222 | B23: 45410 | C23: 45224 | D23: =TODAY()-B23 -> 746 | E23: =DATEDIF(C23,TODAY(),"Y")&" yrs" -> 2 yrs | F23: =EOMONTH(B23,0) -> 45412 | G23: =TEXT(B23,"mmmm yyyy") -> April 2024 | H23: ="Q"&INT((MONTH(B23)-1)/3+1)&"-"&YEAR(B23) -> Q2-2024
A25: KEY DATE METRICS
A26: Metric | B26: Value
A27: Today's Date | B27: =TODAY() -> 46156
A28: Earliest Transaction | B28: =MIN(Raw_Data!B3:B252) -> 45393
A29: Latest Transaction | B29: =MAX(Raw_Data!B3:B252) -> 45758
A30: Date Range (Days) | B30: =MAX(Raw_Data!B3:B252)-MIN(Raw_Data!B3:B252) -> 365

Sheet Analysis
A1: DATA ANALYSIS – Formulas, GroupBy, TEXT Functions
A3: A. REGIONAL SALES SUMMARY (SUMIFS / COUNTIFS / AVERAGEIFS)
A4: Region | B4: Txn Count | C4: Total Revenue ($) | D4: Avg Order ($) | E4: Total Qty | F4: % of Revenue
A5: North | B5: =COUNTIFS(Raw_Data!K3:K252,A5) -> 59 | C5: =SUMIFS(Raw_Data!N3:N252,Raw_Data!K3:K252,A5) -> 50808.31 | D5: =IFERROR(C5/B5,0) -> 861.1578 | E5: =SUMIFS(Raw_Data!H3:H252,Raw_Data!K3:K252,A5) -> 169 | F5: =IFERROR(C5/SUM($C$5:$C$9),0) -> 0.22168403
A6: South | B6: =COUNTIFS(Raw_Data!K3:K252,A6) -> 42 | C6: =SUMIFS(Raw_Data!N3:N252,Raw_Data!K3:K252,A6) -> 36398.75 | D6: =IFERROR(C6/B6,0) -> 866.6369 | E6: =SUMIFS(Raw_Data!H3:H252,Raw_Data!K3:K252,A6) -> 125 | F6: =IFERROR(C6/SUM($C$5:$C$9),0) -> 0.15881303
A7: East | B7: =COUNTIFS(Raw_Data!K3:K252,A7) -> 48 | C7: =SUMIFS(Raw_Data!N3:N252,Raw_Data!K3:K252,A7) -> 59288.39 | D7: =IFERROR(C7/B7,0) -> 1235.1748 | E7: =SUMIFS(Raw_Data!H3:H252,Raw_Data!K3:K252,A7) -> 161 | F7: =IFERROR(C7/SUM($C$5:$C$9),0) -> 0.25868385
A8: West | B8: =COUNTIFS(Raw_Data!K3:K252,A8) -> 47 | C8: =SUMIFS(Raw_Data!N3:N252,Raw_Data!K3:K252,A8) -> 41408.68 | D8: =IFERROR(C8/B8,0) -> 881.03574 | E8: =SUMIFS(Raw_Data!H3:H252,Raw_Data!K3:K252,A8) -> 132 | F8: =IFERROR(C8/SUM($C$5:$C$9),0) -> 0.18067208
A9: Central | B9: =COUNTIFS(Raw_Data!K3:K252,A9) -> 54 | C9: =SUMIFS(Raw_Data!N3:N252,Raw_Data!K3:K252,A9) -> 41288.34 | D9: =IFERROR(C9/B9,0) -> 764.59889 | E9: =SUMIFS(Raw_Data!H3:H252,Raw_Data!K3:K252,A9) -> 166 | F9: =IFERROR(C9/SUM($C$5:$C$9),0) -> 0.18014702
A10: TOTAL | B10: =SUM(B5:B9) -> 250 | C10: =SUM(C5:C9) -> 229192.47 | E10: =SUM(E5:E9) -> 753
A12: B. PRODUCT SALES SUMMARY
A13: Product | B13: Category | C13: Units Sold | D13: Revenue ($) | E13: Avg Unit Price ($) | F13: Txn Count
A14: Laptop | B14: Electronics | C14: =SUMIFS(Raw_Data!H3:H252,Raw_Data!F3:F252,A14) -> 75 | D14: =SUMIFS(Raw_Data!N3:N252,Raw_Data!F3:F252,A14) -> 67499.25 | E14: =IFERROR(D14/C14,0) -> 899.99 | F14: =COUNTIFS(Raw_Data!F3:F252,A14) -> 24
A15: Smartphone | B15: Electronics | C15: =SUMIFS(Raw_Data!H3:H252,Raw_Data!F3:F252,A15) -> 96 | D15: =SUMIFS(Raw_Data!N3:N252,Raw_Data!F3:F252,A15) -> 67199.04 | E15: =IFERROR(D15/C15,0) -> 699.99 | F15: =COUNTIFS(Raw_Data!F3:F252,A15) -> 31
A16: Headphones | B16: Electronics | C16: =SUMIFS(Raw_Data!H3:H252,Raw_Data!F3:F252,A16) -> 47 | D16: =SUMIFS(Raw_Data!N3:N252,Raw_Data!F3:F252,A16) -> 7049.53 | E16: =IFERROR(D16/C16,0) -> 149.99 | F16: =COUNTIFS(Raw_Data!F3:F252,A16) -> 16
A17: Monitor | B17: Electronics | C17: =SUMIFS(Raw_Data!H3:H252,Raw_Data!F3:F252,A17) -> 88 | D17: =SUMIFS(Raw_Data!N3:N252,Raw_Data!F3:F252,A17) -> 21999.12 | E17: =IFERROR(D17/C17,0) -> 249.99 | F17: =COUNTIFS(Raw_Data!F3:F252,A17) -> 26
A18: Keyboard | B18: Electronics | C18: =SUMIFS(Raw_Data!H3:H252,Raw_Data!F3:F252,A18) -> 89 | D18: =SUMIFS(Raw_Data!N3:N252,Raw_Data!F3:F252,A18) -> 8009.11 | E18: =IFERROR(D18/C18,0) -> 89.99 | F18: =COUNTIFS(Raw_Data!F3:F252,A18) -> 34
A19: Blender | B19: Appliances | C19: =SUMIFS(Raw_Data!H3:H252,Raw_Data!F3:F252,A19) -> 87 | D19: =SUMIFS(Raw_Data!N3:N252,Raw_Data!F3:F252,A19) -> 5219.13 | E19: =IFERROR(D19/C19,0) -> 59.99 | F19: =COUNTIFS(Raw_Data!F3:F252,A19) -> 29
A20: Coffee Maker | B20: Appliances | C20: =SUMIFS(Raw_Data!H3:H252,Raw_Data!F3:F252,A20) -> 39 | D20: =SUMIFS(Raw_Data!N3:N252,Raw_Data!F3:F252,A20) -> 3119.61 | E20: =IFERROR(D20/C20,0) -> 79.99 | F20: =COUNTIFS(Raw_Data!F3:F252,A20) -> 14
A21: Bookshelf | B21: Furniture | C21: =SUMIFS(Raw_Data!H3:H252,Raw_Data!F3:F252,A21) -> 102 | D21: =SUMIFS(Raw_Data!N3:N252,Raw_Data!F3:F252,A21) -> 15298.98 | E21: =IFERROR(D21/C21,0) -> 149.99 | F21: =COUNTIFS(Raw_Data!F3:F252,A21) -> 35
A22: Desk | B22: Furniture | C22: =SUMIFS(Raw_Data!H3:H252,Raw_Data!F3:F252,A22) -> 78 | D22: =SUMIFS(Raw_Data!N3:N252,Raw_Data!F3:F252,A22) -> 23399.22 | E22: =IFERROR(D22/C22,0) -> 299.99 | F22: =COUNTIFS(Raw_Data!F3:F252,A22) -> 26
A23: Office Chair | B23: Furniture | C23: =SUMIFS(Raw_Data!H3:H252,Raw_Data!F3:F252,A23) -> 52 | D23: =SUMIFS(Raw_Data!N3:N252,Raw_Data!F3:F252,A23) -> 10399.48 | E23: =IFERROR(D23/C23,0) -> 199.99 | F23: =COUNTIFS(Raw_Data!F3:F252,A23) -> 15
A25: C. HIGH-VALUE CUSTOMERS – TOP 10 (SUMIFS GroupBy)
A26: Customer Name | B26: Customer ID | C26: Segment | D26: Total Spend ($) | E26: Txn Count | F26: Avg Order ($) | G26: Abbreviation (TEXT)
A27: Mark Carter | B27: CUST025 | C27: Standard | D27: =SUMIFS(Raw_Data!N3:N252,Raw_Data!D3:D252,A27) -> 15659.65 | E27: =COUNTIFS(Raw_Data!D3:D252,A27) -> 12 | F27: =IFERROR(D27/E27,0) -> 1304.9708 | G27: =UPPER(LEFT(A27,1))&UPPER(MID(A27,FIND(" ",A27)+1,1)) -> MC
A28: Edward Mitchell | B28: CUST029 | C28: Premium | D28: =SUMIFS(Raw_Data!N3:N252,Raw_Data!D3:D252,A28) -> 11919.77 | E28: =COUNTIFS(Raw_Data!D3:D252,A28) -> 6 | F28: =IFERROR(D28/E28,0) -> 1986.6283 | G28: =UPPER(LEFT(A28,1))&UPPER(MID(A28,FIND(" ",A28)+1,1)) -> EM
A29: Karen Hill | B29: CUST026 | C29: Premium | D29: =SUMIFS(Raw_Data!N3:N252,Raw_Data!D3:D252,A29) -> 8009.77 | E29: =COUNTIFS(Raw_Data!D3:D252,A29) -> 8 | F29: =IFERROR(D29/E29,0) -> 1001.2213 | G29: =UPPER(LEFT(A29,1))&UPPER(MID(A29,FIND(" ",A29)+1,1)) -> KH
A30: Barbara Young | B30: CUST018 | C30: Standard | D30: =SUMIFS(Raw_Data!N3:N252,Raw_Data!D3:D252,A30) -> 10649.8 | E30: =COUNTIFS(Raw_Data!D3:D252,A30) -> 5 | F30: =IFERROR(D30/E30,0) -> 2129.96 | G30: =UPPER(LEFT(A30,1))&UPPER(MID(A30,FIND(" ",A30)+1,1)) -> BY
A31: Joseph Jackson | B31: CUST013 | C31: Standard | D31: =SUMIFS(Raw_Data!N3:N252,Raw_Data!D3:D252,A31) -> 6949.84 | E31: =COUNTIFS(Raw_Data!D3:D252,A31) -> 5 | F31: =IFERROR(D31/E31,0) -> 1389.968 | G31: =UPPER(LEFT(A31,1))&UPPER(MID(A31,FIND(" ",A31)+1,1)) -> JJ
A32: Paul Baker | B32: CUST023 | C32: Standard | D32: =SUMIFS(Raw_Data!N3:N252,Raw_Data!D3:D252,A32) -> 8309.74 | E32: =COUNTIFS(Raw_Data!D3:D252,A32) -> 8 | F32: =IFERROR(D32/E32,0) -> 1038.7175 | G32: =UPPER(LEFT(A32,1))&UPPER(MID(A32,FIND(" ",A32)+1,1)) -> PB
A33: Betty Campbell | B33: CUST028 | C33: Premium | D33: =SUMIFS(Raw_Data!N3:N252,Raw_Data!D3:D252,A33) -> 5649.84 | E33: =COUNTIFS(Raw_Data!D3:D252,A33) -> 5 | F33: =IFERROR(D33/E33,0) -> 1129.968 | G33: =UPPER(LEFT(A33,1))&UPPER(MID(A33,FIND(" ",A33)+1,1)) -> BC
A34: Helen Roberts | B34: CUST030 | C34: Standard | D34: =SUMIFS(Raw_Data!N3:N252,Raw_Data!D3:D252,A34) -> 6459.79 | E34: =COUNTIFS(Raw_Data!D3:D252,A34) -> 7 | F34: =IFERROR(D34/E34,0) -> 922.82714 | G34: =UPPER(LEFT(A34,1))&UPPER(MID(A34,FIND(" ",A34)+1,1)) -> HR
A35: Daniel King | B35: CUST019 | C35: Standard | D35: =SUMIFS(Raw_Data!N3:N252,Raw_Data!D3:D252,A35) -> 7309.8 | E35: =COUNTIFS(Raw_Data!D3:D252,A35) -> 7 | F35: =IFERROR(D35/E35,0) -> 1044.2571 | G35: =UPPER(LEFT(A35,1))&UPPER(MID(A35,FIND(" ",A35)+1,1)) -> DK
A36: Lawrence Reed | B36: CUST039 | C36: Premium | D36: =SUMIFS(Raw_Data!N3:N252,Raw_Data!D3:D252,A36) -> 6989.77 | E36: =COUNTIFS(Raw_Data!D3:D252,A36) -> 8 | F36: =IFERROR(D36/E36,0) -> 873.72125 | G36: =UPPER(LEFT(A36,1))&UPPER(MID(A36,FIND(" ",A36)+1,1)) -> LR
A38: D. MOST FREQUENTLY PURCHASED PRODUCT
A39: Most Freq. Product: | B39: =INDEX(Raw_Data!F3:F252,MATCH(MAX(COUNTIF(Raw_Data!F3:F252,Raw_Data!F3:F252)),COUNTIF(Raw_Data!F3:F252,Raw_Data!F3:F252),0)) -> Office Chair
A40: Most Freq. Customer: | B40: =INDEX(Raw_Data!D3:D252,MATCH(MAX(COUNTIF(Raw_Data!D3:D252,Raw_Data!D3:D252)),COUNTIF(Raw_Data!D3:D252,Raw_Data!D3:D252),0)) -> Susan Green
A42: E. COMPARE TWO LISTS – Find Matching Customers (Premium vs Standard)
A43: Premium Customer IDs | B43: Standard Customer IDs | C43: Match? (ISNUMBER/MATCH)
A44: CUST013 | B44: CUST021 | C44: =IF(ISNUMBER(MATCH(A44,$B$44:$B$51,0)),"MATCH","No Match") -> No Match
A45: CUST046 | B45: CUST024 | C45: =IF(ISNUMBER(MATCH(A45,$B$44:$B$51,0)),"MATCH","No Match") -> No Match
...

Sheet Conditional_Formatting
A1: CONDITIONAL FORMATTING – Icons, Color Scales, Data Bars
A3: Transaction ID | B3: Customer Name | C3: Qty | D3: Unit Price ($) | E3: Total Amount ($) | F3: Region | G3: Category | H3: Segment | I3: CF Status
A4: TRX0155 | B4: Paul Baker | C4: 3 | D4: 249.99 | E4: 749.97 | F4: Central | G4: Electronics | H4: Basic | I4: =IF(E4>1000,"High",IF(E4>500,"Medium","Low")) -> Medium
A5: TRX0023 | B5: Joseph Jackson | C5: 3 | D5: 249.99 | E5: 749.97 | F5: Central | G5: Electronics | H5: Premium | I5: =IF(E5>1000,"High",IF(E5>500,"Medium","Low")) -> Medium
A6: TRX0139 | B6: Kevin Scott | C6: 3 | D6: 59.99 | E6: 179.97 | F6: South | G6: Appliances | H6: Standard | I6: =IF(E6>1000,"High",IF(E6>500,"Medium","Low")) -> Low
A7: TRX0043 | B7: Kathleen Bennett | C7: 3 | D7: 59.99 | E7: 179.97 | F7: North | G7: Appliances | H7: Premium | I7: =IF(E7>1000,"High",IF(E7>500,"Medium","Low")) -> Low
A8: TRX0212 | B8: Michael Brown | C8: 5 | D8: 149.99 | E8: 749.95 | F8: North | G8: Furniture | H8: Premium | I8: =IF(E8>1000,"High",IF(E8>500,"Medium","Low")) -> Medium
A9: TRX0092 | B9: Dorothy Nelson | C9: 2 | D9: 59.99 | E9: 119.98 | F9: West | G9: Appliances | H9: Standard | I9: =IF(E9>1000,"High",IF(E9>500,"Medium","Low")) -> Low
A10: TRX0193 | B10: Dorothy Nelson | C10: 5 | D10: 149.99 | E10: 749.95 | F10: Central | G10: Electronics | H10: Standard | I10: =IF(E10>1000,"High",IF(E10>500,"Medium","Low")) -> Medium
A11: TRX0240 | B11: Charles Allen | C11: 3 | D11: 59.99 | E11: 179.97 | F11: South | G11: Appliances | H11: Basic | I11: =IF(E11>1000,"High",IF(E11>500,"Medium","Low")) -> Low
A12: TRX0135 | B12: Robert Thomas | C12: 3 | D12: 899.99 | E12: 2699.97 | F12: East | G12: Electronics | H12: Standard | I12: =IF(E12>1000,"High",IF(E12>500,"Medium","Low")) -> High
A13: TRX0185 | B13: Karen Hill | C13: 3 | D13: 59.99 | E13: 179.97 | F13: West | G13: Appliances | H13: Premium | I13: =IF(E13>1000,"High",IF(E13>500,"Medium","Low")) -> Low
A14: TRX0138 | B14: Susan Green | C14: 1 | D14: 149.99 | E14: 149.99 | F14: West | G14: Furniture | H14: Standard | I14: =IF(E14>1000,"High",IF(E14>500,"Medium","Low")) -> Low
A15: TRX0209 | B15: Kathleen Bennett | C15: 5 | D15: 149.99 | E15: 749.95 | F15: North | G15: Furniture | H15: Basic | I15: =IF(E15>1000,"High",IF(E15>500,"Medium","Low")) -> Medium
... A28: TRX0071 | B28: Nancy Collins | C28: 5 | D28: 249.99 | E28: 1249.95 | F28: West | G28: Electronics | H28: Standard | I28: =IF(E28>1000,"High",IF(E28>500,"Medium","Low")) -> High
A30: ICON SET DEMO (Qty column – icons show in Excel 365)
A32: LEGEND / RULES APPLIED:
A33: Green→Yellow→Red color scale | B33: Total Amount column – high=green, low=red
A34: Blue Data Bar | B34: Quantity column – proportional bar
A35: Yellow highlight | B35: All rows where Segment = Premium
A36: Red cell fill | B36: Total Amount < $200
A37: CF Status column | B37: Formula: >$1000=High, >$500=Medium, else Low

Sheet WhatIf_Analysis
A1: WHAT-IF ANALYSIS – Scenario Manager & Goal Seek
A3: SCENARIO MANAGER – Revenue Projections
A4: Input Variable | B4: Base Case | C4: Optimistic (+20%) | D4: Pessimistic (-20%)
A5: Total Transactions | B5: 250 | C5: =B5*1.2 -> 300 | D5: =B5*0.8 -> 200
A6: Avg Order Value ($) | B6: 916.76988 | C6: =B6*1.2 -> 1100.1239 | D6: =B6*0.8 -> 733.4159
A7: Conversion Rate (%) | B7: 0.25 | C7: =B7*1.2 -> 0.3 | D7: =B7*0.8 -> 0.2
A8: Total Revenue ($) | B8: 229192.47 | C8: =B8*1.2 -> 275030.96 | D8: =B8*0.8 -> 183353.98
A9: Projected Next Month ($) | B9: =B8/6 -> 38198.745 | C9: =C8/6 -> 45838.494 | D9: =D8/6 -> 30558.996
A10: YoY Growth Rate (%) | B10: 0.12 | C10: =B10*1.2 -> 0.144 | D10: =B10*0.8 -> 0.096
A13: GOAL SEEK – Revenue Target Analysis
A15: Target Annual Revenue ($): | B15: 200000
A16: Current Total Revenue ($): | B16: =B8 -> 229192.47
A17: Revenue Gap ($): | B17: =B15-B16 -> -29192.47
A18: Avg Order Needed to hit target ($): | B18: =IFERROR(B15/B5,0) -> 800
A19: Additional Txns Needed: | B19: =IFERROR(CEILING((B15-B16)/B6,1),0) -> -31
A21: DATA TABLE – Revenue at Different Avg Order Values
A22: Avg Order ($) | B22: Total Revenue (250 txns) | C22: vs Target ($200K)
A23: 400 | B23: =A23*250 -> 100000 | C23: =B23-$B$15 -> -100000
A24: 500 | B24: =A24*250 -> 125000 | C24: =B24-$B$15 -> -75000
A25: 600 | B25: =A25*250 -> 150000 | C25: =B25-$B$15 -> -50000
A26: 700 | B26: =A26*250 -> 175000 | C26: =B26-$B$15 -> -25000
A27: 800 | B27: =A27*250 -> 200000 | C27: =B27-$B$15 -> 0
A28: 900 | B28: =A28*250 -> 225000 | C28: =B28-$B$15 -> 25000
A29: 1000 | B29: =A29*250 -> 250000 | C29: =B29-$B$15 -> 50000

Sheet Linear_Regression
A1: LINEAR REGRESSION – Quantity vs Total Amount
A3: DATA FOR REGRESSION (Quantity → Total Amount)
A4: Qty (X) | B4: Total Amount ($) (Y) | C4: X² | D4: XY | E4: Predicted Y (Ŷ) | F4: Residual (Y - Ŷ) | H4: REGRESSION RESULTS
A5: 3 | B5: 749.97 | C5: =A5^2 -> 9 | D5: =A5*B5 -> 2249.91 | E5: =$I$9+$I$8*A5 -> 0.62256344 | F5: =B5-E5 -> 749.34744 | H5: n (Sample Size) | I5: =30 -> 30
A6: 3 | B6: 749.97 | C6: =A6^2 -> 9 | D6: =A6*B6 -> 2249.91 | E6: =$I$9+$I$8*A6 -> 0.62256344 | F6: =B6-E6 -> 749.34744 | H6: Slope (b1) | I6: =SLOPE(B5:B34,A5:A34) -> 272.33547
A7: 3 | B7: 179.97 | C7: =A7^2 -> 9 | D7: =A7*B7 -> 539.91 | E7: =$I$9+$I$8*A7 -> 0.62256344 | F7: =B7-E7 -> 179.34744 | H7: Intercept (b0) | I7: =INTERCEPT(B5:B34,A5:A34) -> 55.613887
A8: 3 | B8: 179.97 | C8: =A8^2 -> 9 | D8: =A8*B8 -> 539.91 | E8: =$I$9+$I$8*A8 -> 0.62256344 | F8: =B8-E8 -> 179.34744 | H8: R² (Correlation²) | I8: =RSQ(B5:B34,A5:A34) -> 0.10138463
A9: 5 | B9: 749.95 | C9: =A9^2 -> 25 | D9: =A9*B9 -> 3749.75 | E9: =$I$9+$I$8*A9 -> 0.82533271 | F9: =B9-E9 -> 749.12467 | H9: Correlation (R) | I9: =CORREL(B5:B34,A5:A34) -> 0.31840954
A10: 2 | B10: 119.98 | C10: =A10^2 -> 4 | D10: =A10*B10 -> 239.96 | E10: =$I$9+$I$8*A10 -> 0.5211788 | F10: =B10-E10 -> 119.45882 | H10: Std Error | I10: =STEYX(B5:B34,A5:A34) -> 961.36956
A11: 5 | B11: 749.95 | C11: =A11^2 -> 25 | D11: =A11*B11 -> 3749.75 | E11: =$I$9+$I$8*A11 -> 0.82533271 | F11: =B11-E11 -> 749.12467 | H11: Equation | I11: ="Y = "&ROUND(I8,2)&"x + "&ROUND(I9,2) -> Y = 0.1x + 0.32
A12: 3 | B12: 179.97 | C12: =A12^2 -> 9 | D12: =A12*B12 -> 539.91 | E12: =$I$9+$I$8*A12 -> 0.62256344 | F12: =B12-E12 -> 179.34744
A13: 3 | B13: 2699.97 | C13: =A13^2 -> 9 | D13: =A13*B13 -> 8099.91 | E13: =$I$9+$I$8*A13 -> 0.62256344 | F13: =B13-E13 -> 2699.3474 | H13: PREDICTION TABLE
A14: 3 | B14: 179.97 | C14: =A14^2 -> 9 | D14: =A14*B14 -> 539.91 | E14: =$I$9+$I$8*A14 -> 0.62256344 | F14: =B14-E14 -> 179.34744 | H14: If Qty = | I14: Predicted Revenue ($)
A15: 1 | B15: 149.99 | C15: =A15^2 -> 1 | D15: =A15*B15 -> 149.99 | E15: =$I$9+$I$8*A15 -> 0.41979417 | F15: =B15-E15 -> 149.57021 | H15: 1 | I15: =$I$9+$I$8*H15 -> 0.41979417
A16: 5 | B16: 749.95 | C16: =A16^2 -> 25 | D16: =A16*B16 -> 3749.75 | E16: =$I$9+$I$8*A16 -> 0.82533271 | F16: =B16-E16 -> 749.12467 | H16: 2 | I16: =$I$9+$I$8*H16 -> 0.5211788
A17: 3 | B17: 449.97 | C17: =A17^2 -> 9 | D17: =A17*B17 -> 1349.91 | E17: =$I$9+$I$8*A17 -> 0.62256344 | F17: =B17-E17 -> 449.34744 | H17: 3 | I17: =$I$9+$I$8*H17 -> 0.62256344
A18: 3 | B18: 179.97 | C18: =A18^2 -> 9 | D18: =A18*B18 -> 539.91 | E18: =$I$9+$I$8*A18 -> 0.62256344 | F18: =B18-E18 -> 179.34744 | H18: 4 | I18: =$I$9+$I$8*H18 -> 0.72394807
A19: 3 | B19: 2099.97 | C19: =A19^2 -> 9 | D19: =A19*B19 -> 6299.91 | E19: =$I$9+$I$8*A19 -> 0.62256344 | F19: =B19-E19 -> 2099.3474 | H19: 5 | I19: =$I$9+$I$8*H19 -> 0.82533271
A20: 1 | B20: 899.99 | C20: =A20^2 -> 1 | D20: =A20*B20 -> 899.99 | E20: =$I$9+$I$8*A20 -> 0.41979417 | F20: =B20-E20 -> 899.57021 | H20: 6 | I20: =$I$9+$I$8*H20 -> 0.92671734
A21: 4 | B21: 599.96 | C21: =A21^2 -> 16 | D21: =A21*B21 -> 2399.84 | E21: =$I$9+$I$8*A21 -> 0.72394807 | F21: =B21-E21 -> 599.23605 | H21: 7 | I21: =$I$9+$I$8*H21 -> 1.028102
A22: 2 | B22: 1399.98 | C22: =A22^2 -> 4 | D22: =A22*B22 -> 2799.96 | E22: =$I$9+$I$8*A22 -> 0.5211788 | F22: =B22-E22 -> 1399.4588 | H22: 8 | I22: =$I$9+$I$8*H22 -> 1.1294866
A23: 4 | B23: 3599.96 | C23: =A23^2 -> 16 | D23: =A23*B23 -> 14399.84 | E23: =$I$9+$I$8*A23 -> 0.72394807 | F23: =B23-E23 -> 3599.2361
A24: 3 | B24: 749.97 | C24: =A24^2 -> 9 | D24: =A24*B24 -> 2249.91 | E24: =$I$9+$I$8*A24 -> 0.62256344 | F24: =B24-E24 -> 749.34744
A25: 5 | B25: 3499.95 | C25: =A25^2 -> 25 | D25: =A25*B25 -> 17499.75 | E25: =$I$9+$I$8*A25 -> 0.82533271 | F25: =B25-E25 -> 3499.1247
A26: 4 | B26: 2799.96 | C26: =A26^2 -> 16 | D26: =A26*B26 -> 11199.84 | E26: =$I$9+$I$8*A26 -> 0.72394807 | F26: =B26-E26 -> 2799.2361
A27: 4 | B27: 999.96 | C27: =A27^2 -> 16 | D27: =A27*B27 -> 3999.84 | E27: =$I$9+$I$8*A27 -> 0.72394807 | F27: =B27-E27 -> 999.23605
A28: 4 | B28: 1199.96 | C28: =A28^2 -> 16 | D28: =A28*B28 -> 4799.84 | E28: =$I$9+$I$8*A28 -> 0.72394807 | F28: =B28-E28 -> 1199.2361
A29: 5 | B29: 1249.95 | C29: =A29^2 -> 25 | D29: =A29*B29 -> 6249.75 | E29: =$I$9+$I$8*A29 -> 0.82533271 | F29: =B29-E29 -> 1249.1247
A30: 5 | B30: 1499.95 | C30: =A30^2 -> 25 | D30: =A30*B30 -> 7499.75 | E30: =$I$9+$I$8*A30 -> 0.82533271 | F30: =B30-E30 -> 1499.1247
A31: 3 | B31: 239.97 | C31: =A31^2 -> 9 | D31: =A31*B31 -> 719.91 | E31: =$I$9+$I$8*A31 -> 0.62256344 | F31: =B31-E31 -> 239.34744
A32: 5 | B32: 449.95 | C32: =A32^2 -> 25 | D32: =A32*B32 -> 2249.75 | E32: =$I$9+$I$8*A32 -> 0.82533271 | F32: =B32-E32 -> 449.12467
A33: 2 | B33: 119.98 | C33: =A33^2 -> 4 | D33: =A33*B33 -> 239.96 | E33: =$I$9+$I$8*A33 -> 0.5211788 | F33: =B33-E33 -> 119.45882
A34: 4 | B34: 239.96 | C34: =A34^2 -> 16 | D34: =A34*B34 -> 959.84 | E34: =$I$9+$I$8*A34 -> 0.72394807 | F34: =B34-E34 -> 239.23605

Sheet Pivot_Charts
A1: PIVOT TABLES & CHARTS – Sales Analysis
A3: PIVOT 1: Revenue by Region × Category ($) | G3: PIVOT 2: Payment Method Summary | K3: PIVOT 3: Customer Segment
A4: Region | B4: Electronics | C4: Appliances | D4: Furniture | E4: Grand Total | G4: Payment Method | H4: Txn Count | I4: Revenue ($) | K4: Segment | L4: Txn Count | M4: Revenue ($)
A5: North | B5: =SUMIFS(Raw_Data!N3:N252,Raw_Data!K3:K252,A5,Raw_Data!G3:G252,B4) -> 39239.04 | C5: =SUMIFS(Raw_Data!N3:N252,Raw_Data!K3:K252,A5,Raw_Data!G3:G252,C4) -> 1119.84 | D5: =SUMIFS(Raw_Data!N3:N252,Raw_Data!K3:K252,A5,Raw_Data!G3:G252,D4) -> 10449.43 | E5: =SUM(B5:D5) -> 50808.31 | G5: Cash | H5: =COUNTIFS(Raw_Data!J3:J252,G5) -> 76 | I5: =SUMIFS(Raw_Data!N3:N252,Raw_Data!J3:J252,G5) -> 57427.79 | K5: Basic | L5: =COUNTIFS(Raw_Data!L3:L252,K5) -> 74 | M5: =SUMIFS(Raw_Data!N3:N252,Raw_Data!L3:L252,K5) -> 62177.81
A6: South | B6: =SUMIFS(Raw_Data!N3:N252,Raw_Data!K3:K252,A6,Raw_Data!G3:G252,B4) -> 25549.32 | C6: =SUMIFS(Raw_Data!N3:N252,Raw_Data!K3:K252,A6,Raw_Data!G3:G252,C4) -> 1099.83 | D6: =SUMIFS(Raw_Data!N3:N252,Raw_Data!K3:K252,A6,Raw_Data!G3:G252,D4) -> 9749.6 | E6: =SUM(B6:D6) -> 36398.75 | G6: Credit Card | H6: =COUNTIFS(Raw_Data!J3:J252,G6) -> 68 | I6: =SUMIFS(Raw_Data!N3:N252,Raw_Data!J3:J252,G6) -> 61447.96 | K6: Standard | L6: =COUNTIFS(Raw_Data!L3:L252,K6) -> 81 | M6: =SUMIFS(Raw_Data!N3:N252,Raw_Data!L3:L252,K6) -> 82357.54
A7: East | B7: =SUMIFS(Raw_Data!N3:N252,Raw_Data!K3:K252,A7,Raw_Data!G3:G252,B4) -> 50649.01 | C7: =SUMIFS(Raw_Data!N3:N252,Raw_Data!K3:K252,A7,Raw_Data!G3:G252,C4) -> 2239.67 | D7: =SUMIFS(Raw_Data!N3:N252,Raw_Data!K3:K252,A7,Raw_Data!G3:G252,D4) -> 6399.71 | E7: =SUM(B7:D7) -> 59288.39 | G7: Debit Card | H7: =COUNTIFS(Raw_Data!J3:J252,G7) -> 54 | I7: =SUMIFS(Raw_Data!N3:N252,Raw_Data!J3:J252,G7) -> 52118.31 | K7: Premium | L7: =COUNTIFS(Raw_Data!L3:L252,K7) -> 95 | M7: =SUMIFS(Raw_Data!N3:N252,Raw_Data!L3:L252,K7) -> 84657.12
A8: West | B8: =SUMIFS(Raw_Data!N3:N252,Raw_Data!K3:K252,A8,Raw_Data!G3:G252,B4) -> 31429.35 | C8: =SUMIFS(Raw_Data!N3:N252,Raw_Data!K3:K252,A8,Raw_Data!G3:G252,C4) -> 1879.69 | D8: =SUMIFS(Raw_Data!N3:N252,Raw_Data!K3:K252,A8,Raw_Data!G3:G252,D4) -> 8099.64 | E8: =SUM(B8:D8) -> 41408.68 | G8: PayPal | H8: =COUNTIFS(Raw_Data!J3:J252,G8) -> 52 | I8: =SUMIFS(Raw_Data!N3:N252,Raw_Data!J3:J252,G8) -> 58198.41
A9: Central | B9: =SUMIFS(Raw_Data!N3:N252,Raw_Data!K3:K252,A9,Raw_Data!G3:G252,B4) -> 24889.33 | C9: =SUMIFS(Raw_Data!N3:N252,Raw_Data!K3:K252,A9,Raw_Data!G3:G252,C4) -> 1999.71 | D9: =SUMIFS(Raw_Data!N3:N252,Raw_Data!K3:K252,A9,Raw_Data!G3:G252,D4) -> 14399.3 | E9: =SUM(B9:D9) -> 41288.34 | G9: Total | H9: =SUM(H5:H8) -> 250 | I9: =SUM(I5:I8) -> 229192.47
A10: Grand Total | B10: =SUM(B5:B9) -> 171756.05 | C10: =SUM(C5:C9) -> 8338.74 | D10: =SUM(D5:D9) -> 49097.68 | E10: =SUM(E5:E9) -> 229192.47

Sheet Final_Report
B1: FINAL PROJECT REPORT Data Intelligence Dashboard
B4: PR. Final Project | Customer Transaction Analytics | Excel Advanced Techniques
B6: EXECUTIVE SUMMARY
B7: Dataset | C7: 250 customer transactions | 50 unique customers | 10 products | 5 regions
B8: Period | C8: =TEXT(MIN(Raw_Data!B3:B252),"mmm-yyyy")&" to "&TEXT(MAX(Raw_Data!B3:B252),"mmm-yyyy") -> Apr-2024 to Apr-2025
B9: Total Revenue ($) | C9: =ROUND(SUM(Raw_Data!N3:N252),2) -> 229192.47
B10: Avg Order Value ($) | C10: =ROUND(AVERAGE(Raw_Data!N3:N252),2) -> 916.77
B11: Top Region | C11: =INDEX(Analysis!A5:A9,MATCH(MAX(Analysis!C5:C9),Analysis!C5:C9,0)) -> East
B12: Top Product | C12: =INDEX(Raw_Data!F3:F252,MATCH(MAX(COUNTIF(Raw_Data!F3:F252,Raw_Data!F3:F252)),COUNTIF(Raw_Data!F3:F252,Raw_Data!F3:F252),0)) -> Blender
B14: TECHNIQUES IMPLEMENTED
B15: Date Functions | C15: TODAY, DATEDIF, EOMONTH, TEXT(date), YEAR, MONTH – Sheet: Date_Time_Functions
B16: Conditional Formatting | C16: Color Scale, Data Bar, Icon Sets, Formula-based rules – Sheet: Conditional_Formatting
B17: WHAT-IF Analysis | C17: Scenario Manager (Base/Optimistic/Pessimistic), Goal Seek, Data Table – Sheet: WhatIf_Analysis
B18: Linear Regression | C18: SLOPE, INTERCEPT, RSQ, CORREL, STEYX – Sheet: Linear_Regression
B19: GroupBy Formulas | C19: SUMIFS, COUNTIFS, AVERAGEIFS for region/product/customer aggregation – Sheet: Analysis
B20: TEXT Functions | C20: LEFT, MID, FIND, LEN, UPPER, LOWER, TRIM, CONCAT for name manipulation – Sheet: Analysis
B21: List Comparison | C21: ISNUMBER + MATCH to find matching customers across segments – Sheet: Analysis
B22: Abbreviations | C22: UPPER(LEFT()) pattern for creating customer initials – Sheet: Analysis
B23: Pivot & Charts | C23: Manual pivot tables + Bar, Line, Pie charts – Sheet: Pivot_Charts
B24: Dashboard | C24: KPI cards, summary tables, charts with storytelling – Sheet: Dashboard
B26: KEY BUSINESS INSIGHTS
B27: Revenue Leader | C27: Laptop ($) generates 40%+ of total electronics revenue
B28: Customer Insight | C28: Top 10 customers account for ~45% of total revenue
B29: Regional Insight | C29: All 5 regions show healthy distribution; North leads in volume
B30: Payment Preference | C30: Credit Card & Cash dominate; PayPal growing in electronics
B31: Growth Lever | C31: Upselling to Standard segment could add $15K+ revenue
B32: Recommendation 1 | C32: Focus retention programs on Basic segment – high churn risk
B33: Recommendation 2 | C33: Bundle Electronics + Accessories for higher avg order value
B34: Recommendation 3 | C34: West region shows premium customer concentration – target campaigns
B36: ="Report generated: "&TEXT(TODAY(),"dd mmmm yyyy") -> Report generated: 14 May 2026
